C:\Users\osama\OneDrive\Desktop\Usama_dev\Fine_tuning_DINOv3\dino_env\Lib\site-packages\torch\utils\data\dataloader.py:666: UserWarning: 'pin_memory' argument is set as true but no accelerator is found, then device pinned memory won't be used.
  warnings.warn(warn_msg)
Traceback (most recent call last):
  File "C:\Users\osama\OneDrive\Desktop\Usama_dev\Fine_tuning_DINOv3\dinov3_project\main.py", line 130, in <module>
    main()
  File "C:\Users\osama\OneDrive\Desktop\Usama_dev\Fine_tuning_DINOv3\dinov3_project\main.py", line 119, in main
    best_val_acc = run_training_epochs(
                   ^^^^^^^^^^^^^^^^^^^^
  File "C:\Users\osama\OneDrive\Desktop\Usama_dev\Fine_tuning_DINOv3\dinov3_project\utils\helpers.py", line 90, in run_training_epochs
    tr_loss, tr_acc, tr_time = train_one_epoch(
                               ^^^^^^^^^^^^^^^^
  File "C:\Users\osama\OneDrive\Desktop\Usama_dev\Fine_tuning_DINOv3\dinov3_project\training\trainer.py", line 30, in train_one_epoch
    for batch_idx, (images, target) in enumerate(loader):
                                       ^^^^^^^^^^^^^^^^^
  File "C:\Users\osama\OneDrive\Desktop\Usama_dev\Fine_tuning_DINOv3\dino_env\Lib\site-packages\torch\utils\data\dataloader.py", line 494, in __iter__
    return self._get_iterator()
           ^^^^^^^^^^^^^^^^^^^^
  File "C:\Users\osama\OneDrive\Desktop\Usama_dev\Fine_tuning_DINOv3\dino_env\Lib\site-packages\torch\utils\data\dataloader.py", line 427, in _get_iterator
    return _MultiProcessingDataLoaderIter(self)
           ^^^^^^^^^^^^^^^^^^^^^^^^^^^^^^^^^^^^
  File "C:\Users\osama\OneDrive\Desktop\Usama_dev\Fine_tuning_DINOv3\dino_env\Lib\site-packages\torch\utils\data\dataloader.py", line 1172, in __init__
    w.start()
  File "C:\Users\osama\AppData\Local\Programs\Python\Python312\Lib\multiprocessing\process.py", line 121, in start
    self._popen = self._Popen(self)
                  ^^^^^^^^^^^^^^^^^
  File "C:\Users\osama\AppData\Local\Programs\Python\Python312\Lib\multiprocessing\context.py", line 224, in _Popen
    return _default_context.get_context().Process._Popen(process_obj)
           ^^^^^^^^^^^^^^^^^^^^^^^^^^^^^^^^^^^^^^^^^^^^^^^^^^^^^^^^^^
  File "C:\Users\osama\AppData\Local\Programs\Python\Python312\Lib\multiprocessing\context.py", line 337, in _Popen
    return Popen(process_obj)
           ^^^^^^^^^^^^^^^^^^
  File "C:\Users\osama\AppData\Local\Programs\Python\Python312\Lib\multiprocessing\popen_spawn_win32.py", line 95, in __init__
    reduction.dump(process_obj, to_child)
  File "C:\Users\osama\AppData\Local\Programs\Python\Python312\Lib\multiprocessing\reduction.py", line 60, in dump
    ForkingPickler(file, protocol).dump(obj)
AttributeError: Can't get local object 'collate_with_transform_classification.<locals>._collate'
